Workbook

Sheet How to fill it
B2: 02_sizing — how to fill it in (Assignment 2)
B4: WHICH PROJECT IS THIS ABOUT?
B5: Your team's own project: the customer-support agent your team chose for the course (one of the proposals P1–P8 in the project document, or your own idea). One sheet per team, committed as 02_sizing.xlsx in your Git repository. It is NOT about Paylio: Paylio is the fictional company of the in-class exercise; it only appears in column H of the Inputs tab, to show what a filled-in cell looks like.
B7: WHAT THE SHEET ANSWERS
B8: Is your agent worth building for the company? You get: the net value per year in three scenarios (pessimistic, base, optimistic), an expected value, the comparison with doing nothing and with another project the same team could do, a decision (go / no-go / conditional go), the one assumption that flips the decision, and a build / buy / orchestrate score. Your memo (02_investment_memo.md) explains these numbers in one page.
B10: WHERE YOUR NUMBERS COME FROM
B11: 1) Your company's numbers are in your proposal (table at the bottom of this tab): treat them as measured — they are your company's logs. 2) Orders of magnitude from the Session 2 slides (a human ticket costs €5–15 all-in; an LLM conversation €0.02–0.20): analogy. 3) Everything else is your estimate: write guess, and say in the note how you would check it. Every yellow cell gets a source type and a note.
B13: STEP BY STEP — about one hour, as a team. Type only in the yellow cells.
B14: Step | C14: Where | D14: What to enter | E14: Tip
B15: 1 · Volume and human cost | C15: Inputs, rows 6–9 | D15: Tickets per month; number of support agents; what ONE agent costs the company per year (all-in); the cost of one ticket handled by a human. | E15: From your proposal. Row 10 gives the agent time per ticket from headcount (Paylio: 60 × €45k ÷ 480,000 ≈ €5.6; €10 all-in with team leads, QA and tools); row 11 the tickets per agent per day.
B16: 2 · Your categories | C16: Inputs, A14:A16 and rows 14–16 | D16: Rename the three categories of work your agent deals with — ticket types, requests, incidents, accounts (e.g. P4: refund requests, delivery questions, account issues) — and give each one's share of the volume. | E16: Fewer than three? Set Include = 0 (rows 34–36) for the unused ones.
B17: 3 · Automatable share | C17: Inputs, rows 18–20 | D17: In each category, the share of tickets the agent could handle at all (answerable from the documentation, the policy, the data it can see). | E17: Guess from a sample of tickets — and say how you would check it.
B18: 4 · Deflection realised | C18: Inputs, rows 22–24 | D18: Of those, the share actually resolved without a human once live. | E18: Usually THE assumption that flips the decision: mark it “guess → S4 test”.
B19: 5 · Errors and what they cost | C19: Inputs, rows 26–32 | D19: The error rate per category, and the cost in € of one wrong answer (customer retries, refund leakage, penalty, churn, a legal case). | E19: The costly categories are where a human must stay — that is a scope decision (step 6).
B20: 6 · Scope | C20: Inputs, rows 34–36 | D20: 1 = the agent handles this category, 0 = it does not. | E20: Try 0 on the riskiest category and watch the decision.
B21: 7 · Adoption by quarter | C21: Inputs, rows 39–42 | D21: The share of the deflectable volume actually handled in Q1, Q2, Q3, Q4. | E21: Never 100 % in Q1 — Octopus Energy went from a handful of emails to 34 %, then 45 %.
B22: 8 · AI cost | C22: Inputs, rows 45–46 | D22: The AI cost per conversation (tokens × price) and the retry overhead. | E22: €0.02–0.20 per conversation; recheck token prices the day you fill it in.
B23: 9 · Fixed costs | C23: Inputs, rows 49–56 | D23: Integration, evaluation, supervision (people in the loop, in FTE), monitoring and on-call, re-evaluation when the model changes. | E23: The human in the loop is a cost line, not free.
B24: 10 · The two comparisons | C24: Inputs, rows 59–60 | D24: How much the current process improves each year on its own (do-nothing), and the yearly value of the next-best project the same team could do (name it in the note). | E24: The hurdle is another project, not zero.
B25: 11 · Probabilities | C25: Inputs, row 63 | D25: How likely you find the pessimistic, base and optimistic scenarios. | E25: Must sum to 1 (row 64 checks it).
... B28: 14 · Write the memo | C28: 02_investment_memo.md | D28: Recommendation on line one, the four CFO questions, one line on build / buy / orchestrate. | E28: Same base case as this sheet.
B30: STARTING NUMBERS FROM THE PROJECT DOCUMENT
B31: Proposal | C31: Company numbers | D31: The pain | E31: Kind of value
B32: P1 · HR & payroll SaaS | C32: 2,500 customer companies · 40,000 tickets/month · 60 support agents | D32: 55 % of tickets are “how do I…” questions already answered in the documentation; peaks at month end | E32: Work avoided
B33: P2 · B2B payments fintech | C33: 800 merchants · 12,000 tickets/month | D33: Agents spend 40 % of handling time reading transaction history and past tickets | E33: Time saved (copilot)
B34: P3 · DevOps / observability | C34: 5,000 accounts · tickets ×10 during incidents (normal volume not given: estimate it) | D34: During an outage, 70 % of tickets say the same thing | E34: Incident load — tickets per incident × incidents a year
B35: P4 · E-commerce logistics | C35: 15,000 merchants · 25,000 tickets/month | D35: 30 % of tickets are label refunds; refunds under €20 cost more to process than they are worth | E35: Work avoided; the cost of error is refund leakage
B36: P5 · Ed-tech LMS | C36: 14 countries · 6 languages · 20 agents (volume not given: estimate it) | D36: Tickets in Portuguese, Polish, Arabic wait 2–3× longer | E36: Work avoided — use the categories for languages
B37: P6 · Project-management SaaS | C37: 30,000 SMB accounts · 9,000 tickets/month · 8 % annual churn | D37: Churn signals visible in support weeks before cancellation | E37: Work avoided + revenue retained (Other value)
B38: P7 · Cybersecurity SaaS | C38: 400 enterprise accounts · 6,000 tickets/month · 25 engineers · SLA P1 = 1 h, P2 = 4 h | D38: Misprioritised tickets cause SLA breaches and penalties | E38: Time saved + penalties avoided (Other value)
B39: P8 · Hospitality-tech | C39: 3,000 hotels (volume not given: estimate it) · reviews.csv for real data | D39: 20 % of tickets are analysis requests; answer today in 4 days | E39: Time saved — analysis requests answered faster
B40: Own project | C40: The numbers of your 00_pitch.md | D40: Your pain, expressed as a cost | E40: Pick the kind of value below; invent plausible numbers and label them
B42: NOT ONLY TICKETS — OTHER KINDS OF VALUE, WITH WORKED EXAMPLES
B43: Every agent is sized the same way: volume × share in scope × success rate × value per success − AI cost − cost of errors − fixed costs. Only the unit and the value change. Pick the line that matches your agent (you can combine two). Numbers below are illustrative — replace them with yours.
B44: Kind of value | C44: Typical for | D44: What goes where in the sheet | E44: Illustrative example
B45: Work avoided (deflection) | C45: P1, P4, P5 | D45: Volume = tickets · success rate = deflection · value per unit = human cost of one ticket. | E45: P1: 40,000 tickets × 55 % “how do I” × 68 % automatable × your deflection rate (say 50 %) × €10 ≈ €75k a month at full adoption.
B46: Time saved (copilot) | C46: P2, P7 (triage), P8 | D46: Volume = tickets or requests the agent helps with · success rate = share of handling time saved · value per unit = human cost of one. | E46: P2: 12,000 tickets × 100 % with the copilot × 20 % of time saved × €10 ≈ €24k a month.
B47: Revenue retained | C47: P6 | D47: Use an Other value row (67–68): accounts at risk that reach support × share saved × yearly revenue per account. | E47: P6: 30,000 accounts × 8 % churn = 2,400 lost a year; half open a ticket first; 10 % saved = 120 × €1,200 ≈ €144k a year.
B48: Penalties avoided | C48: P7 | D48: Use an Other value row: breaches a year × share avoided × penalty per breach (from the contracts). | E48: P7: 240 SLA breaches a year × 30 % avoided × €2,000 ≈ €144k a year.
B49: Faster answers, incident load | C49: P3, P8 | D49: Volume = requests or incident tickets (incidents a year × tickets per incident ÷ 12) · value = agent time per ticket; the speed gain goes in the memo. | E49: P3: 20 incidents a year × 1,500 tickets each ÷ 12 = 2,500 tickets a month.
...

Sheet Inputs
A1: 02_sizing — your agent · Inputs
A2: Keelpay copilot (routing + drafting) - sizing built bottom-up from the frozen brief in the README. 'Low' = pessimistic, 'High' = optimistic. Yellow = input; green font = link to the Flow tab, where time saved, error and AI costs are derived. Time-saved kind of value: the 'success rate' is the share of handling time saved, applied to every ticket the copilot handles.
A4: Parameter | B4: Unit | C4: Low (pessimistic) | D4: Base | E4: High (optimistic) | F4: Source type | G4: Note / where the number comes from
A5: VOLUME AND HUMAN COST
A6: Volume per month (tickets, requests, conversations…) | B6: tickets | C6: 20000 | D6: 20500 | E6: 21000 | F6: given | G6: Scenario data (README): ~20,000 tickets a month today. Base and High add the average year-1 effect of merchant growth (about +5% / +10% by year end); the do-nothing text in 01 says volume grows.
A7: Tier-1 support agents (headcount) | B7: people | C7: 25 | D7: 25 | E7: 25 | F7: guess | G7: 20,000 tickets x ~10 min hands-on / ~130 productive hours per agent. Test: headcount and timesheets of a real support team.
A8: Cost of ONE agent to the company per year (all-in) | B8: € / year | C8: 50000 | D8: 50000 | E8: 50000 | F8: guess | G8: All-in yearly cost of a customer adviser in France. Analogy to check: job postings (France Travail, Michael Page) plus employer charges. Source it on the day.
A9: Cost of ONE unit handled by a human (ticket, request…) | B9: € / ticket | C9: 6 | D9: 7 | E9: 8 | F9: analogy | G9: Course order of magnitude: a human ticket costs EUR 5-15 all-in (S2 slides). Base 7 = agent time (row 10, ~5.2) x ~1.35 for the part of team leads, QA and tools that scales with agent time.
A10: Check — cost per ticket from headcount, base = agents × cost per agent ÷ tickets per year | B10: € / ticket | D10: =IFERROR(D7*D8/(D6*12),"") | G10: Formula, not an input: agents × cost per agent ÷ (volume × 12) = the agent time per unit. Row 9 should be equal or higher (Paylio: €5.6 of agent time, €10 all-in).
A11: Check — tickets per agent per working day, base (21 working days a month) | B11: tickets | D11: =IFERROR(D6/D7/21,"") | G11: Formula, not an input: volume ÷ agents ÷ 21 — a sanity check (Paylio ≈ 32 tickets a day).
A12: TICKET CATEGORIES
A13: Share of the volume by category (rename the three categories in A14:A16 — the other blocks follow)
A14: Payment status and payouts | B14: share | C14: 0.45 | D14: 0.45 | E14: 0.45 | F14: guess | G14: Share of tickets by type. Test: category tags in the helpdesk over three months.
A15: Disputes and chargebacks | B15: share | C15: 0.2 | D15: 0.2 | E15: 0.2 | F15: guess | G15: Same test. Disputes are the costly category (deadlines).
A16: Technical / API and compliance | B16: share | C16: 0.35 | D16: 0.35 | E16: 0.35 | F16: guess | G16: Same test.
A17: Automatable share (answerable from documentation)
A18: =" "&TRIM($A$14) | B18: share | C18: 1 | D18: 1 | E18: 1 | F18: decision | G18: The copilot reads and routes every ticket, so every ticket is in the base for time saved.
A19: =" "&TRIM($A$15) | B19: share | C19: 1 | D19: 1 | E19: 1 | F19: decision | G19: The copilot reads and routes every ticket, so every ticket is in the base for time saved.
A20: =" "&TRIM($A$16) | B20: share | C20: 1 | D20: 1 | E20: 1 | F20: decision | G20: The copilot reads and routes every ticket, so every ticket is in the base for time saved.
A21: Success rate on the automatable share (deflection — or share of time saved, see the guide)
A22: =" "&TRIM($A$14) | B22: share | C22: =Flow!C15 | D22: =Flow!D15 | E22: =Flow!E15 | F22: guess | G22: Share of handling time saved = routing slice + drafting slice, derived on the Flow tab. THE assumption that flips the decision: test on the S4 prototype and the S6 A/B.
A23: =" "&TRIM($A$15) | B23: share | C23: =Flow!C15 | D23: =Flow!D15 | E23: =Flow!E15 | F23: guess | G23: Share of handling time saved = routing slice + drafting slice, derived on the Flow tab. THE assumption that flips the decision: test on the S4 prototype and the S6 A/B.
A24: =" "&TRIM($A$16) | B24: share | C24: =Flow!C15 | D24: =Flow!D15 | E24: =Flow!E15 | F24: guess | G24: Share of handling time saved = routing slice + drafting slice, derived on the Flow tab. THE assumption that flips the decision: test on the S4 prototype and the S6 A/B.
A25: Error rate — share of AI answers that are wrong
A26: =" "&TRIM($A$14) | B26: share | C26: =Flow!C19/Flow!C15 | D26: =Flow!D19/Flow!D15 | E26: =Flow!E19/Flow!E15 | F26: guess | G26: Uncaught serious errors per ticket handled (Flow tab) divided by the share of time saved, because the template applies error cost to time-saved-equivalent tickets.
A27: =" "&TRIM($A$15) | B27: share | C27: =Flow!C20/Flow!C15 | D27: =Flow!D20/Flow!D15 | E27: =Flow!E20/Flow!E15 | F27: guess | G27: Uncaught serious errors per ticket handled (Flow tab) divided by the share of time saved, because the template applies error cost to time-saved-equivalent tickets.
A28: =" "&TRIM($A$16) | B28: share | C28: =Flow!C21/Flow!C15 | D28: =Flow!D21/Flow!D15 | E28: =Flow!E21/Flow!E15 | F28: guess | G28: Uncaught serious errors per ticket handled (Flow tab) divided by the share of time saved, because the template applies error cost to time-saved-equivalent tickets.
A29: Cost of one wrong answer
A30: =" "&TRIM($A$14) | B30: € / error | C30: 200 | D30: 150 | E30: 120 | F30: guess | G30: Wrong payment reply or ticket stuck in the wrong desk: extra contacts, goodwill credit, churn tail. Pessimistic is higher.
A31: =" "&TRIM($A$15) | B31: € / error | C31: 600 | D31: 400 | E31: 300 | F31: guess | G31: Missed chargeback deadline or wrong amount told: chargeback fees (analogy: Mastercard 2025, $128 per chargeback) plus lost dispute plus complaint risk.
A32: =" "&TRIM($A$16) | B32: € / error | C32: 450 | D32: 300 | E32: 250 | F32: guess | G32: Missed compliance hold or API incident handled late: regulatory exposure, merchant churn. Legal/reputational line (see governance).
A33: Include category in scope? (1 = yes, 0 = no)
A34: =" "&TRIM($A$14) | B34: 1/0 | C34: 1 | D34: 1 | E34: 1 | F34: decision | G34: Scope decision. Try 0 on disputes and watch the decision.
A35: =" "&TRIM($A$15) | B35: 1/0 | C35: 1 | D35: 1 | E35: 1 | F35: decision | G35: Scope decision. Try 0 on disputes and watch the decision.
A36: =" "&TRIM($A$16) | B36: 1/0 | C36: 1 | D36: 1 | E36: 1 | F36: decision | G36: Scope decision. Try 0 on disputes and watch the decision.
A38: ADOPTION RAMP — share of deflectable volume actually handled, by quarter
A39: Q1 | B39: share | C39: 0.05 | D39: 0.15 | E39: 0.25 | F39: guess | G39: Pessimistic = the guardrail fails and the rollout stops at about 10% (S4/Q1 gate), not a world with heavy errors and full ramp. Staged rollout: routing starts on low-critical tickets, each step conditional on a guardrail holding (template: staged like Octopus Energy).
A40: Q2 | B40: share | C40: 0.1 | D40: 0.35 | E40: 0.5 | F40: guess | G40: staged like Octopus Energy (a handful → 34 % → 45 %); each step conditional on a guardrail holding
A41: Q3 | B41: share | C41: 0.1 | D41: 0.55 | E41: 0.7 | F41: guess | G41: staged like Octopus Energy (a handful → 34 % → 45 %); each step conditional on a guardrail holding
A42: Q4 | B42: share | C42: 0.1 | D42: 0.7 | E42: 0.85 | F42: guess | G42: staged like Octopus Energy (a handful → 34 % → 45 %); each step conditional on a guardrail holding
...

Sheet Flow
A1: 02_sizing - Flow: how the inputs are derived (routing + drafting)
A2: Yellow = input (Low = pessimistic, High = optimistic). Black = formula. Rows 15, 24, 30 and 35 feed the Inputs tab.
A4: Line | B4: Unit | C4: Low | D4: Base | E4: High | F4: Source type | G4: Note / test
A5: SUB-CASE A - ROUTING (read the message, route the ticket)
A6: Share of handling time: reading and routing | B6: share | C6: 0.15 | D6: 0.15 | E6: 0.15 | F6: given | G6: README frozen brief.
A7: Share of tickets routed automatically (clear and not critical) | B7: share | C7: 0.35 | D7: 0.55 | E7: 0.7 | F7: guess | G7: The rest goes to human triage. Test: gold set at several thresholds (S4).
A8: Cut in reading and routing time on those tickets | B8: share | C8: 0.5 | D8: 0.65 | E8: 0.8 | F8: guess | G8: The agent no longer reads for routing, but still sees the case. Test: time study with and without (S5).
A9: Time saved by A (share of total handling time) | B9: share | C9: =C6*C7*C8 | D9: =D6*D7*D8 | E9: =E6*E7*E8 | F9: formula | G9: Slice x auto-lane share x cut. Triage tickets save nothing here (conservative).
A10: SUB-CASE B - DRAFTING (find the payment and history, write the reply)
A11: Share of handling time: finding the payment and history, and writing | B11: share | C11: 0.45 | D11: 0.45 | E11: 0.45 | F11: given | G11: README frozen brief.
A12: Cut in that time with a cited draft | B12: share | C12: 0.12 | D12: 0.22 | E12: 0.3 | F12: analogy | G12: Published gain is about -13% time per issue overall (Brynjolfsson et al., QJE 2025) on all work; this slice is where a draft acts, so a larger cut here. Test: S5/S6.
A13: Share of tickets correctly routed (the draft is usable) | B13: share | C13: 0.88 | D13: 0.92 | E13: 0.95 | F13: guess | G13: Today 6 in 7 (86%, given). The copilot improves it; a misrouted ticket gets a draft for the wrong desk and no saving.
A14: Time saved by B (share of total handling time) | B14: share | C14: =C11*C12*C13 | D14: =D11*D12*D13 | E14: =E11*E12*E13 | F14: formula | G14: Slice x cut x correctly routed share.
A15: TOTAL time saved at full adoption (share of handling time) | B15: share | C15: =C9+C14 | D15: =D9+D14 | E15: =E9+E14 | F15: formula | G15: Feeds Inputs rows 22-24. Cross-check: published about 13%; the course's own P2 example uses 20%.
A17: ERRORS AND AI COST (per ticket the copilot handles)
A19: Uncaught serious errors per ticket handled - payment status | B19: share | C19: 0.001 | D19: 0.0005 | E19: 0.0003 | F19: guess | G19: INCREMENTAL uncaught serious errors versus today (humans also misroute 1 in 7): auto-route error nobody catches, or wrong draft validated unread, with a real consequence. Test: seeded errors in S4 (hypothesis 4).
A20: Uncaught serious errors per ticket handled - disputes | B20: share | C20: 0.0025 | D20: 0.0012 | E20: 0.0007 | F20: guess | G20: Higher: deadlines and amounts.
A21: Uncaught serious errors per ticket handled - technical / compliance | B21: share | C21: 0.0015 | D21: 0.0008 | E21: 0.0005 | F21: guess
A22: AI cost per ticket handled - routing model call | B22: EUR | C22: 0.003 | D22: 0.002 | E22: 0.001 | F22: guess | G22: Self-hosted small model: marginal cost is near zero, the endpoint is a fixed cost (Read options tab).
A23: AI cost per ticket handled - draft (retrieval, queries, generation) | B23: EUR | C23: 0.01 | D23: 0.005 | E23: 0.003 | F23: guess | G23: Self-hosted drafter: the marginal cost per ticket is near zero (retrieval, database queries, power); the endpoint is a fixed cost in Inputs row 54.
A24: AI cost per ticket handled - total | B24: EUR | C24: =C22+C23 | D24: =D22+D23 | E24: =E22+E23 | F24: formula | G24: Feeds Inputs row 45.
A25: OTHER VALUE - hand-overs avoided
A26: Misroute rate today | B26: share | C26: =1/7 | D26: =1/7 | E26: =1/7 | F26: given | G26: 1 ticket in 7 first lands in the wrong desk (README).
A27: Misroute rate on tickets the copilot handles | B27: share | C27: =1-C13 | D27: =1-D13 | E27: =1-E13 | F27: formula | G27: Equal to 1 minus the correctly routed share of row 13. Test: reroute counts in S4 (gold set) then S6.
A28: Cost of one hand-over | B28: EUR | C28: 2 | D28: 3 | E28: 4 | F28: guess | G28: Queue delay and merchant irritation only: the second desk re-reading is hands-on time already inside the 15% slice. Test: time study.
A29: Year-1 adoption factor (average of the four quarters) | B29: share | C29: =AVERAGE(Inputs!C39:C42) | D29: =AVERAGE(Inputs!D39:D42) | E29: =AVERAGE(Inputs!E39:E42) | F29: formula
A30: Hand-overs avoided, year-1 value | B30: EUR / yr | C30: =Inputs!C6*12*(C26-C27)*C29*C28 | D30: =Inputs!D6*12*(D26-D27)*D29*D28 | E30: =Inputs!E6*12*(E26-E27)*E29*E28 | F30: formula | G30: Feeds Inputs row 67.
A31: NEXT-BEST PROJECT - rules-only ticket-to-transaction attach and routing on structured fields (no AI)
A32: Share of handling time saved | B32: share | C32: 0.03 | D32: 0.06 | E32: 0.09 | F32: guess | G32: Removes the search for the payment (about half of slice B) for tickets with an ID or amount, and routes the structured part. Test: observe 20 tickets.
A33: Adoption factor | B33: share | C33: 0.6 | D33: 0.7 | E33: 0.8 | F33: guess | G33: A rule needs less ramp-up than a model, but it also has a build quarter.
A34: Yearly cost (build amortised + upkeep) | B34: EUR / yr | C34: 35000 | D34: 30000 | E34: 25000 | F34: guess | G34: Integration is the same work as step 3 of the copilot, so it is not lost if the copilot is built later.
A35: Net annual value of the next-best project | B35: EUR / yr | C35: =Inputs!C6*12*C32*Inputs!C9*C33-C34 | D35: =Inputs!D6*12*D32*Inputs!D9*D33-D34 | E35: =Inputs!E6*12*E32*Inputs!E9*E33-E34 | F35: formula | G35: Feeds Inputs row 60 (the hurdle).

Sheet Read options
A1: 02_sizing - Read options: monthly cost of the five ways to read a ticket (step 1)
A2: All prices are guesses to recheck on the day. Effectiveness is NOT scored here: it is measured on the gold set in S4. This tab answers the cost and data-control criteria only.
A4: ASSUMPTIONS
A5: Tickets per month | B5: tickets | C5: =Inputs!D6 | D5: given | H5: Scenario data.
A6: Input tokens per ticket (instructions, examples, message) | B6: tokens | C6: 1200 | D6: guess | H6: Prompted options need instructions and a few examples; the fine-tuned model needs far fewer.
A7: Output tokens per ticket (the JSON) | B7: tokens | C7: 150 | D7: guess
A8: API price, small model - input | B8: EUR / M tokens | C8: 0.15 | D8: guess | H8: Recheck on the provider's price page the day you use it.
A9: API price, small model - output | B9: EUR / M tokens | C9: 0.6 | D9: guess
A10: API price, large model - input | B10: EUR / M tokens | C10: 3 | D10: guess
A11: API price, large model - output | B11: EUR / M tokens | C11: 15 | D11: guess
A12: Router endpoint in our cloud account - small fine-tuned model, CPU, scale to zero | B12: EUR / month | C12: 10 | D12: guess | H12: Container on Cloud Run with min-instances 0, billed per second, same pattern as the Museum Guide demo (free tier at its volume). 20,000 tickets x ~4 s x 2 vCPU is about 160k vCPU-seconds a month, around the free tier. Recheck the price list.
A13: Fine-tuning runs per year | B13: runs | C13: 4 | D13: guess | H13: Initial training plus re-training when the gold set or taxonomy changes.
A14: Cost of one fine-tuning run | B14: EUR | C14: 300 | D14: guess | H14: Small model, short run on a rented GPU. Does not include people time (that is in evaluation and supervision).
A15: Larger open-source model (7-30B), prompted - drafter class, GPU scale to zero | B15: EUR / month | C15: 100 | D15: guess | H15: GPU billed per second, no always-on cost: tickets are processed asynchronously, so a cold start of tens of seconds is acceptable. About 20,000 x 15 s = 83 GPU-hours at roughly EUR 0.8-1 an hour. Recheck the price list.
A16: Option | C16: EUR / month | D16: EUR / year | E16: Tickets leave Keelpay? | F16: Version pinned by us? | H16: How it is computed / note
A17: A - Deterministic rules | C17: 20 | D17: =C17*12 | E17: no | F17: yes | H17: Small service, mostly maintenance time (not counted).
A18: B - Classical ML / small encoder | C18: 60 | D18: =C18*12 | E18: no | F18: yes | H18: CPU service; labelling effort sits in evaluation.
A19: C - Open-source LLM, prompted, in our cloud account | C19: =C15 | D19: =C19*12 | E19: no | F19: yes | H19: Larger model, bigger GPU than D.
A20: D - Small fine-tuned LLM, in our cloud account | C20: =C12+C13*C14/12 | D20: =C20*12 | E20: no | F20: yes | H20: Endpoint plus training runs spread over the year.
A21: E1 - External API, small model (REFERENCE ONLY, excluded) | C21: =C5*(C6*C8+C7*C9)/1000000 | D21: =C21*12 | E21: yes | F21: no (provider can retire it) | H21: Excluded by the data constraint: tickets never leave Keelpay's cloud. Shown to price the constraint.
A22: E2 - External API, large model (REFERENCE ONLY, excluded) | C22: =C5*(C6*C10+C7*C11)/1000000 | D22: =C22*12 | E22: yes | F22: no (provider can retire it) | H22: Same, large model.
A24: BREAK-EVEN
A25: API cost per ticket, small model (E1) | C25: =(C6*C8+C7*C9)/1000000
A26: Volume above which self-hosting D costs less than E1 | B26: tickets / month | C26: =IFERROR(C20/C25,"")
A27: ... as a multiple of our volume | C27: =IFERROR(C26/C5,"")
A28: Reading: the data constraint (README) removes E, so the real comparison is A, B, C and D inside our cloud. With scale-to-zero hosting (billed per second, as in the Museum Guide demo) all four cost tens of euros a month, far below the value of accuracy (one point of routing accuracy is worth about EUR 14k a year in hand-overs). So cost does not decide: D must win on the gold set (accuracy on urgent tickets, valid JSON, latency). E is shown only to price the constraint: a few tens of euros a month, so the constraint costs almost nothing and is cheap insurance for tickets that carry payment data.

Sheet Upside
A1: 02_sizing — your agent · Upside (bottom-up tree per category, year 1)
A2: All cells are formulas linked to Inputs (green = link to another sheet). Read each block top to bottom: it is the tree from the S2 slides, per ticket category.
A4: Line | B4: Unit | C4: Low | D4: Base | E4: High | F4: How it is computed
A5: Year-1 adoption factor (average of the four quarters) | C5: =IFERROR(AVERAGE(Inputs!C39:C42),0) | D5: =IFERROR(AVERAGE(Inputs!D39:D42),0) | E5: =IFERROR(AVERAGE(Inputs!E39:E42),0) | F5: → AVERAGE(Inputs ramp Q1..Q4)
A7: =UPPER(TRIM(Inputs!A14))
A8: Tickets per month in this category | B8: tickets | C8: =Inputs!C$6*Inputs!C14 | D8: =Inputs!D$6*Inputs!D14 | E8: =Inputs!E$6*Inputs!E14 | F8: → tickets/month × share
A9: Automatable tickets per month | B9: tickets | C9: =C8*Inputs!C18 | D9: =D8*Inputs!D18 | E9: =E8*Inputs!E18 | F9: × automatable share
A10: Deflected per month at steady state (if in scope) | B10: tickets | C10: =C9*Inputs!C22*Inputs!C34 | D10: =D9*Inputs!D22*Inputs!D34 | E10: =E9*Inputs!E22*Inputs!E34 | F10: × deflection realised × include flag
A11: Deflected in year 1, with the adoption ramp | B11: tickets / yr | C11: =C10*12*C$5 | D11: =D10*12*D$5 | E11: =E10*12*E$5 | F11: × 12 × year-1 adoption factor
A12: Gross value — human work avoided | B12: € / yr | C12: =C11*Inputs!C$9 | D12: =D11*Inputs!D$9 | E12: =E11*Inputs!E$9 | F12: × fully loaded cost of a human ticket
A13: Expected cost of wrong answers | B13: € / yr | C13: =C11*Inputs!C26*Inputs!C30 | D13: =D11*Inputs!D26*Inputs!D30 | E13: =E11*Inputs!E26*Inputs!E30 | F13: deflected × error rate × cost of one wrong answer — the tail, priced
A14: AI handling cost (tokens, retries) | B14: € / yr | C14: =C11*Inputs!C$45*Inputs!C$46 | D14: =D11*Inputs!D$45*Inputs!D$46 | E14: =E11*Inputs!E$45*Inputs!E$46 | F14: deflected × cost per conversation × retry overhead
A15: Net contribution of this category | B15: € / yr | C15: =C12-C13-C14 | D15: =D12-D13-D14 | E15: =E12-E13-E14 | F15: gross − error cost − AI cost
A17: =UPPER(TRIM(Inputs!A15))
A18: Tickets per month in this category | B18: tickets | C18: =Inputs!C$6*Inputs!C15 | D18: =Inputs!D$6*Inputs!D15 | E18: =Inputs!E$6*Inputs!E15 | F18: → tickets/month × share
A19: Automatable tickets per month | B19: tickets | C19: =C18*Inputs!C19 | D19: =D18*Inputs!D19 | E19: =E18*Inputs!E19 | F19: × automatable share
A20: Deflected per month at steady state (if in scope) | B20: tickets | C20: =C19*Inputs!C23*Inputs!C35 | D20: =D19*Inputs!D23*Inputs!D35 | E20: =E19*Inputs!E23*Inputs!E35 | F20: × deflection realised × include flag
A21: Deflected in year 1, with the adoption ramp | B21: tickets / yr | C21: =C20*12*C$5 | D21: =D20*12*D$5 | E21: =E20*12*E$5 | F21: × 12 × year-1 adoption factor
A22: Gross value — human work avoided | B22: € / yr | C22: =C21*Inputs!C$9 | D22: =D21*Inputs!D$9 | E22: =E21*Inputs!E$9 | F22: × fully loaded cost of a human ticket
A23: Expected cost of wrong answers | B23: € / yr | C23: =C21*Inputs!C27*Inputs!C31 | D23: =D21*Inputs!D27*Inputs!D31 | E23: =E21*Inputs!E27*Inputs!E31 | F23: deflected × error rate × cost of one wrong answer — the tail, priced
A24: AI handling cost (tokens, retries) | B24: € / yr | C24: =C21*Inputs!C$45*Inputs!C$46 | D24: =D21*Inputs!D$45*Inputs!D$46 | E24: =E21*Inputs!E$45*Inputs!E$46 | F24: deflected × cost per conversation × retry overhead
A25: Net contribution of this category | B25: € / yr | C25: =C22-C23-C24 | D25: =D22-D23-D24 | E25: =E22-E23-E24 | F25: gross − error cost − AI cost
A27: =UPPER(TRIM(Inputs!A16))
A28: Tickets per month in this category | B28: tickets | C28: =Inputs!C$6*Inputs!C16 | D28: =Inputs!D$6*Inputs!D16 | E28: =Inputs!E$6*Inputs!E16 | F28: → tickets/month × share
A29: Automatable tickets per month | B29: tickets | C29: =C28*Inputs!C20 | D29: =D28*Inputs!D20 | E29: =E28*Inputs!E20 | F29: × automatable share
A30: Deflected per month at steady state (if in scope) | B30: tickets | C30: =C29*Inputs!C24*Inputs!C36 | D30: =D29*Inputs!D24*Inputs!D36 | E30: =E29*Inputs!E24*Inputs!E36 | F30: × deflection realised × include flag
A31: Deflected in year 1, with the adoption ramp | B31: tickets / yr | C31: =C30*12*C$5 | D31: =D30*12*D$5 | E31: =E30*12*E$5 | F31: × 12 × year-1 adoption factor
A32: Gross value — human work avoided | B32: € / yr | C32: =C31*Inputs!C$9 | D32: =D31*Inputs!D$9 | E32: =E31*Inputs!E$9 | F32: × fully loaded cost of a human ticket
A33: Expected cost of wrong answers | B33: € / yr | C33: =C31*Inputs!C28*Inputs!C32 | D33: =D31*Inputs!D28*Inputs!D32 | E33: =E31*Inputs!E28*Inputs!E32 | F33: deflected × error rate × cost of one wrong answer — the tail, priced
A34: AI handling cost (tokens, retries) | B34: € / yr | C34: =C31*Inputs!C$45*Inputs!C$46 | D34: =D31*Inputs!D$45*Inputs!D$46 | E34: =E31*Inputs!E$45*Inputs!E$46 | F34: deflected × cost per conversation × retry overhead
A35: Net contribution of this category | B35: € / yr | C35: =C32-C33-C34 | D35: =D32-D33-D34 | E35: =E32-E33-E34 | F35: gross − error cost − AI cost
A37: TOTALS — ALL CATEGORIES IN SCOPE
A38: Tickets deflected in year 1 | B38: tickets / yr | C38: =C11+C21+C31 | D38: =D11+D21+D31 | E38: =E11+E21+E31 | F38: sum of the three categories
A39: Gross value — human work avoided | B39: € / yr | C39: =C12+C22+C32 | D39: =D12+D22+D32 | E39: =E12+E22+E32 | F39: sum of the three categories
A40: Expected cost of wrong answers | B40: € / yr | C40: =C13+C23+C33 | D40: =D13+D23+D33 | E40: =E13+E23+E33 | F40: sum of the three categories
A41: AI handling cost | B41: € / yr | C41: =C14+C24+C34 | D41: =D14+D24+D34 | E41: =E14+E24+E34 | F41: sum of the three categories
A42: Net variable contribution (before fixed costs) | B42: € / yr | C42: =C15+C25+C35 | D42: =D15+D25+D35 | E42: =E15+E25+E35 | F42: sum of the three categories
A44: Share of all tickets deflected in year 1 | B44: share | C44: =IF(Inputs!C6=0,0,C38/(Inputs!C6*12)) | D44: =IF(Inputs!D6=0,0,D38/(Inputs!D6*12)) | E44: =IF(Inputs!E6=0,0,E38/(Inputs!E6*12)) | F44: sanity check: the SOM in ticket terms

Sheet Decision
A1: 02_sizing — your agent · Costs & Decision
A2: Three scenarios → expected value → two comparisons (do-nothing, hurdle). Green = links to Upside / Inputs; black = formulas.
A4: Line | B4: Unit | C4: Low (pessimistic) | D4: Base | E4: High (optimistic) | F4: How it is computed
A5: VALUE
A6: Net variable contribution (Upside) + other value (Inputs rows 67–68) | B6: € / yr | C6: =Upside!C42+N(Inputs!C67)+N(Inputs!C68) | D6: =Upside!D42+N(Inputs!D67)+N(Inputs!D68) | E6: =Upside!E42+N(Inputs!E67)+N(Inputs!E68) | F6: gross − error cost − AI cost, all categories in scope
A8: FIXED AND SEMI-FIXED COSTS
A9: Integration, amortised | B9: € / yr | C9: =IFERROR(Inputs!C49/Inputs!C50,0) | D9: =IFERROR(Inputs!D49/Inputs!D50,0) | E9: =IFERROR(Inputs!E49/Inputs!E50,0) | F9: one-off ÷ amortisation years
A10: Evaluation — eval-set and graders | B10: € / yr | C10: =Inputs!C51 | D10: =Inputs!D51 | E10: =Inputs!E51
A11: Supervision — humans in the loop | B11: € / yr | C11: =Inputs!C52*Inputs!C53 | D11: =Inputs!D52*Inputs!D53 | E11: =Inputs!E52*Inputs!E53 | F11: FTE × cost per FTE
A12: Monitoring and on-call | B12: € / yr | C12: =Inputs!C54 | D12: =Inputs!D54 | E12: =Inputs!E54
A13: Re-evaluation at model changes | B13: € / yr | C13: =Inputs!C55*Inputs!C56 | D13: =Inputs!D55*Inputs!D56 | E13: =Inputs!E55*Inputs!E56 | F13: changes per year × cost per change
A14: Total fixed and semi-fixed | B14: € / yr | C14: =SUM(C9:C13) | D14: =SUM(D9:D13) | E14: =SUM(E9:E13)
A16: NET ANNUAL VALUE AND EXPECTED VALUE
A17: Net annual value of the project, year 1 | B17: € / yr | C17: =C6-C14 | D17: =D6-D14 | E17: =E6-E14 | F17: net variable contribution − fixed costs
A18: Scenario probability | B18: p | C18: =Inputs!C63 | D18: =Inputs!D63 | E18: =Inputs!E63 | F18: from Inputs
A19: Expected value (Σ p × net value) | B19: € / yr | D19: =SUMPRODUCT(C17:E17,C18:E18) | F19: the single number — but read the three above it first
A21: THE TWO COMPARISONS
A22: Do-nothing: value of the current process improving on its own | B22: € / yr | C22: =Inputs!C59*Inputs!C6*12*Inputs!C9 | D22: =Inputs!D59*Inputs!D6*12*Inputs!D9 | E22: =Inputs!E59*Inputs!E6*12*Inputs!E9 | F22: efficiency gain × annual tickets × cost per ticket — not zero
A23: Next-best project (the hurdle) | B23: € / yr | C23: =Inputs!C60 | D23: =Inputs!D60 | E23: =Inputs!E60 | F23: from Inputs
A24: EV minus do-nothing | B24: € / yr | D24: =D19-D22
A25: EV minus hurdle | B25: € / yr | D25: =D19-D23
A26: Pessimistic case clears the hurdle? | D26: =IF(C17>=C23,"yes","no")
A27: Decision (formula — you still write the memo) | D27: =IF(Inputs!D6="","— fill in the Inputs tab first —",IF(ABS(Inputs!D64-1)>0.001,"— scenario probabilities must sum to 1 —",IF(D19<D22,"NO-GO — does not beat do-nothing",IF(D19<D23,"NO-GO — does not beat the next-best project",IF(C17<D23,"CONDITIONAL GO — EV clears the hurdle, the pessimistic case does not: test the deflection assumption first","GO")))))
A29: SENSITIVITY — the assumption that flips the decision
A30: Base case, varying the total share of handling time saved (all categories). Everything else at Base; error and AI cost are per ticket handled, so they do not move.
A31: Total time saved (share of handling time) | C31: Net annual value | D31: vs hurdle | E31: vs do-nothing | F31: Reading
A32: 0.1 | C32: =Inputs!D6*12*Upside!D$5*A32*Inputs!D$9-Upside!D40-Upside!D41-D14+N(Inputs!$D$67)+N(Inputs!$D$68) | D32: =C32-D23 | E32: =C32-D22 | F32: =IF(Inputs!D6="","",IF(C32<D22,"below do-nothing",IF(C32<D23,"below the hurdle — the next-best project wins","clears the hurdle")))
A33: 0.15 | C33: =Inputs!D6*12*Upside!D$5*A33*Inputs!D$9-Upside!D40-Upside!D41-D14+N(Inputs!$D$67)+N(Inputs!$D$68) | D33: =C33-D23 | E33: =C33-D22 | F33: =IF(Inputs!D6="","",IF(C33<D22,"below do-nothing",IF(C33<D23,"below the hurdle — the next-best project wins","clears the hurdle")))
A34: 0.2 | C34: =Inputs!D6*12*Upside!D$5*A34*Inputs!D$9-Upside!D40-Upside!D41-D14+N(Inputs!$D$67)+N(Inputs!$D$68) | D34: =C34-D23 | E34: =C34-D22 | F34: =IF(Inputs!D6="","",IF(C34<D22,"below do-nothing",IF(C34<D23,"below the hurdle — the next-best project wins","clears the hurdle")))
A35: 0.25 | C35: =Inputs!D6*12*Upside!D$5*A35*Inputs!D$9-Upside!D40-Upside!D41-D14+N(Inputs!$D$67)+N(Inputs!$D$68) | D35: =C35-D23 | E35: =C35-D22 | F35: =IF(Inputs!D6="","",IF(C35<D22,"below do-nothing",IF(C35<D23,"below the hurdle — the next-best project wins","clears the hurdle")))
A36: 0.3 | C36: =Inputs!D6*12*Upside!D$5*A36*Inputs!D$9-Upside!D40-Upside!D41-D14+N(Inputs!$D$67)+N(Inputs!$D$68) | D36: =C36-D23 | E36: =C36-D22 | F36: =IF(Inputs!D6="","",IF(C36<D22,"below do-nothing",IF(C36<D23,"below the hurdle — the next-best project wins","clears the hurdle")))
A38: Read down the table: the time-saved share at which the reading changes is the flip point. Name it in the memo - the S4 prototype and S6 A/B must measure it.
A40: NOT IN THE TEMPLATE - additional readings used in the memo (the formula above stays as the course defines it)
A41: Base-case net annual value, year 1, above zero? | D41: =IF(D17>0,"yes","no")
A42: Expected value above zero and above the next-best project? | D42: =IF(AND(D19>0,D19>D23),"yes","no")
A43: Base-case net value at steady-state adoption (Q4 level held for a full year) | B43: EUR / yr | D43: =(Upside!D42+N(Inputs!D67))/Upside!D5*Inputs!D42-D14 | F43: Variable contribution and hand-overs scaled from the year-1 average ramp to the Q4 ramp, minus fixed costs. Year 1 carries the ramp-up; later years do not.

Sheet Build or buy
A1: 02_sizing — your agent · Build, buy or orchestrate?
A2: Score each option from 1 (bad) to 5 (good) on each question, weight what matters to your company (weights sum to 100 %). Then write one line in the memo — “We orchestrate because…” — and the condition that would change it. See the build / buy / orchestrate slides of Session 2 (39–40).
A4: # | B4: Question | C4: Weight | D4: Build | E4: Buy | F4: Orchestrate | G4: Why — one line per score that is not obvious
A5: 01 | B5: Strategy — Is it our edge? Would a competitor buying the same tool erase our advantage? | C5: 0.08 | D5: 4 | E5: 2 | F5: 4 | G5: Routing and drafting on our ledger and dispute rules are the edge; a generic vendor copilot is not.
A6: 02 | B6: Strategy — Do we own data or know-how that no vendor has? | C6: 0.12 | D6: 5 | E6: 2 | F6: 5 | G6: Ledger, dispute history and desk policies are ours.
A7: 03 | B7: Fit & speed — Does a product already do 80 % of the job — our languages, channels, integrations? | C7: 0.1 | D7: 2 | E7: 4 | F7: 3 | G7: Vendor copilots summarise and draft but do not read our ledger or route by our desk rules out of the box.
A8: 04 | B8: Fit & speed — Must it be live in weeks, or can it take quarters? | C8: 0.08 | D8: 1 | E8: 5 | F8: 3 | G8: Build takes quarters; a vendor is weeks.
A9: 05 | B9: Fit & speed — Do we have the people to build it and to run it — evals, on-call, re-evaluation? | C9: 0.08 | D9: 2 | E9: 4 | F9: 3 | G9: We have no ML-ops team; orchestrating managed pieces lowers the run burden.
A10: 06 | B10: Money — 3-year total cost: fees per resolution or per seat vs the seven cost lines of a build | C10: 0.12 | D10: 2 | E10: 4 | F10: 3 | G10: At ~25 seats a vendor is cheap; the build carries the fixed lines of the Decision tab.
A11: 07 | B11: Money — At what volume does per-resolution pricing cost more than building? (break-even below) | C11: 0.08 | D11: 3 | E11: 4 | F11: 3 | G11: See break-even below.
A12: 08 | B12: Risk & control — Where does our data go — GDPR, residency, may the vendor train on it? | C12: 0.14 | D12: 5 | E12: 2 | F12: 4 | G12: Self-hosted keeps tickets in-house; a vendor needs EU residency and a no-training DPA to match.
A13: 09 | B13: Risk & control — Can we leave — exit clause, export of data, prompts and eval-sets? | C13: 0.08 | D13: 5 | E13: 2 | F13: 4 | G13: Exit: we keep prompts, gold set and model; a vendor locks the workflow.
A14: 10 | B14: Risk & control — Who is liable when it is wrong, and can we see why it answered — logs, evals? | C14: 0.12 | D14: 5 | E14: 2 | F14: 4 | G14: Own logs and evals vs vendor black box; liability stays with Keelpay either way.
B16: Weights must sum to 100 % | C16: =SUM(C5:C14)
B17: Weighted score (1–5) | D17: =IFERROR(IF(COUNT(D5:D14)=0,"",SUMPRODUCT($C$5:$C$14,D5:D14)/SUM($C$5:$C$14)),"") | E17: =IFERROR(IF(COUNT(E5:E14)=0,"",SUMPRODUCT($C$5:$C$14,E5:E14)/SUM($C$5:$C$14)),"") | F17: =IFERROR(IF(COUNT(F5:F14)=0,"",SUMPRODUCT($C$5:$C$14,F5:F14)/SUM($C$5:$C$14)),"")
B18: Highest weighted score | D18: =IF(COUNT(D17:F17)=0,"— score the three options —",IF(ABS(C16-1)>0.001,"— weights must sum to 100 % —",INDEX($D$4:$F$4,MATCH(MAX(D17:F17),D17:F17,0)))) | G18: The score informs the decision; the memo makes it. If two options are within 0.3, say which condition would decide.
A21: BREAK-EVEN — buying per resolution vs running it yourself (base case, rough)
B22: Vendor price per resolution | D22: =25*45*12/Upside!D38 | E22: EUR / resolution | G22: Per-seat pricing expressed per time-saved-equivalent ticket: 25 seats x about EUR 45 a month (guess; vendor copilots are priced per seat; template tip: Intercom Fin listed $0.99 per resolution in 2025). Recheck the vendor price.
B23: Tickets deflected in year 1 (base) | D23: =Upside!D38 | E23: tickets / yr | G23: from Upside
B24: Annual vendor fees | D24: =IFERROR(D22*D23,0) | E24: € / yr | G24: price × resolutions
B25: Your own AI handling cost (tokens, retries) | D25: =Upside!D41 | E25: € / yr | G25: from Upside
B26: Integration (amortised) + evaluation + re-evaluation | D26: =Decision!D9+Decision!D10+Decision!D13 | E26: € / yr | G26: from Decision — the build-specific fixed lines
B27: Running it yourself — comparable cost | D27: =D25+D26 | E27: € / yr | G27: supervision and monitoring stay in both options, so they are left out
B28: Buying is cheaper by | D28: =D27-D24 | E28: € / yr | G28: negative = running it yourself is cheaper at this volume
